<?xml version="1.0" ?>
<sdf version="1.5">
  <model name="lok_sim">
    <pose>0 0 1.5 0 0 0</pose>
    <static>false</static>
    <link name="body">
      <inertial>
        <mass>1000</mass>
        <inertia> <!-- inertias are tricky to compute -->
          <!-- http://gazebosim.org/tutorials?tut=inertia&cat=build_robot -->
          <ixx>4515.2</ixx>       <!-- for a box: ixx = 0.083 * mass * (y*y + z*z) -->
          <ixy>0.0</ixy>         <!-- for a box: ixy = 0 -->
          <ixz>0.0</ixz>         <!-- for a box: ixz = 0 -->
          <iyy>33200</iyy>       <!-- for a box: iyy = 0.083 * mass * (x*x + z*z) -->
          <iyz>0.0</iyz>         <!-- for a box: iyz = 0 -->
          <izz>31075.2</izz>       <!-- for a box: izz = 0.083 * mass * (x*x + y*y) -->
        </inertia>
      </inertial>
      <collision name="collision">
        <geometry>
          <box>
            <size>6 1.2 2</size>
          </box>
        </geometry>
      </collision>
      <visual name="visual">
        <geometry>
          <box>
            <size>6 1.2 2</size>
          </box>
        </geometry>
      </visual>
    </link>
    <include>
      <uri>model://rr_wheel</uri>
      <pose>1 -0.72 -0.8 0 0 -1.57</pose>
      <name>front_right_wheel</name>
    </include>
    <joint name = 'body_wh_fr_r' type = 'revolute'>
      <parent>body</parent>
      <child>front_right_wheel::wheel_body</child>
      <axis>
        <xyz>1 0 0</xyz>
      </axis>
      </joint>
      <include>
      <uri>model://rr_wheel</uri>
      <pose>1 0.72 -0.8 0 0 1.57</pose>
      <name>front_left_wheel</name>
    </include>
    <joint name = 'body_wh_fr_l' type = 'revolute'>
      <parent>body</parent>
      <child>front_left_wheel::wheel_body</child>
      <axis>
        <xyz>1 0 0</xyz>
      </axis>
      </joint>
      <include>
      <uri>model://rr_wheel</uri>
      <pose>-1 -0.72 -0.8 0 0 -1.57</pose>
      <name>rear_right_wheel</name>
    </include>
    <joint name = 'body_wh_re_r' type = 'revolute'>
      <parent>body</parent>
      <child>rear_right_wheel::wheel_body</child>
      <axis>
        <xyz>1 0 0</xyz>
      </axis>
      </joint>
      <include>
      <uri>model://rr_wheel</uri>
      <pose>-1 0.72 -0.8 0 0 1.57</pose>
      <name>rear_left_wheel</name>
    </include>
    <joint name = 'body_wh_re_l' type = 'revolute'>
      <parent>body</parent>
      <child>rear_left_wheel::wheel_body</child>
      <axis>
        <xyz>1 0 0</xyz>
      </axis>
      </joint>
    <include>
    <uri>model://t334</uri>
    <pose>0.6 0.0 0.3 0 0 0</pose> 
    <name>lok_body</name> 
    </include>
    <joint name = 'body_lok_body' type = 'fixed'>
      <parent>body</parent>
      <child>lok_body::link</child>
      </joint>
  </model>
</sdf>
